<?xml version="1.0"?>
<robot name="my_robot" xmlns:xacro="http://www.ros.org/wiki/xacro">

    <xacro:include filename="$(find robot_description)/urdf/properties.xacro"/>
    
    <xacro:property name="base_width" value="0.5" />
    <xacro:property name="base_length" value="0.5" />
    <xacro:property name="base_height" value="0.06" />
    <xacro:property name="rail_width" value="0.04" />
    <xacro:property name="rail_length" value="0.04" />
    <xacro:property name="main_rail_size" value="0.02" />
    <xacro:property name="motor_radius" value="0.03" />
    <xacro:property name="motor_height" value="0.06" />

    <link name="base_link">
        <visual>
            <geometry>
                <box size="${base_width} ${base_length} ${base_height}" />
            </geometry>
            <origin xyz="0 0 ${base_height/2.0}" rpy="0 0 0" />
            <material name="grey" />
        </visual> 
    </link>

    <link name="motorA_link">
        <visual>
            <geometry>
                <cylinder radius="${motor_radius}" length="${motor_height}"/> 
            </geometry>
            <origin xyz="0 0 ${motor_height/2.0}" rpy="0 0 0" />
            <material name="blue" />
        </visual>
    </link>

    <link name="motorB_link">
        <visual>
            <geometry>
                <cylinder radius="${motor_radius}" length="${motor_height}"/>  
            </geometry>
            <origin xyz="0 0 ${motor_height/2.0}" rpy="0 0 0" />
            <material name="yellow" />
        </visual>
    </link>

    <link name="railA_link">
        <visual>
            <geometry>
                <box size="${base_length-2.0*motor_radius} ${rail_width} ${rail_length}" />
            </geometry>
            <origin xyz="0 0 0" rpy="0 0 0" />
            <material name="grey" />
        </visual> 
    </link>

    <link name="railB_link">
        <visual>
            <geometry>
                <box size="${base_length-2.0*motor_radius} ${rail_width} ${rail_length}" />
            </geometry>
            <origin xyz="0 0 0" rpy="0 0 0" />
            <material name="grey" />
        </visual> 
    </link>

    <link name="main_rail_link">
        <visual>
            <geometry>
                <box size="${main_rail_size} ${base_length-2.0*rail_length} ${main_rail_size}" />
            </geometry>
            <origin xyz="0 ${-(base_length-2.0*rail_length)/2.0} 0" rpy="0 0 0" />
            <material name="dark_grey" />
        </visual> 
    </link>

    <joint name="base_motorA_joint" type="continuous">
        <parent link="base_link"/>
        <child link="motorA_link"/>
        <origin xyz="${-base_width/2.0 + motor_radius} ${-base_width/2.0 + motor_radius} ${base_height}" rpy="0 0 0" />
        <axis xyz="0 0 1"/>
    </joint>

    <joint name="base_motorB_joint" type="continuous">
        <parent link="base_link"/>
        <child link="motorB_link"/>
        <origin xyz="${-base_width/2.0 + motor_radius} ${base_width/2.0 - motor_radius} ${base_height}" rpy="0 0 0" />
        <axis xyz="0 0 1"/>
    </joint>

     <joint name="base_railA_joint" type="fixed">
        <parent link="base_link"/>
        <child link="railA_link"/>
        <origin xyz="${motor_radius} ${base_width/2.0-rail_width/2.0} ${base_height + rail_length/2.0}" rpy="0 0 0" />
    </joint>

     <joint name="base_railB_joint" type="fixed">
        <parent link="base_link"/>
        <child link="railB_link"/>
        <origin xyz="${motor_radius} ${-base_width/2.0+rail_width/2.0} ${base_height + rail_length/2.0}" rpy="0 0 0" />
    </joint>

     <joint name="railA_main_rail_joint" type="prismatic">
        <parent link="railA_link"/>
        <child link="main_rail_link"/>
        <origin xyz="0 ${-rail_length/2.0} 0" rpy="0 0 0" />
        <limit lower="${-(base_length/2.0 -main_rail_size*2.0)}" upper="${base_length/2.0-main_rail_size*2.0}" effort="100" velocity="100"/>
    </joint>

</robot>